{
 "cells": [
  {
   "cell_type": "code",
   "execution_count": 179,
   "id": "f976d7eb-e609-452d-93ad-3ca4c47cb96a",
   "metadata": {},
   "outputs": [],
   "source": [
    "import numpy as np\n",
    "import pandas as pd\n",
    "import plotly.express as px\n",
    "import plotly.graph_objects as go\n",
    "import dash_bootstrap_components as dbc\n",
    "from dash import html,dcc,Input,Output\n",
    "\n",
    "from sklearn.linear_model import LinearRegression\n",
    "from sklearn.model_selection import train_test_split"
   ]
  },
  {
   "cell_type": "markdown",
   "id": "a4d0e57d-012a-46fc-b427-6ce091061c08",
   "metadata": {},
   "source": [
    "# 資料處理"
   ]
  },
  {
   "cell_type": "code",
   "execution_count": 140,
   "id": "f39524ba-7ad2-4902-8d64-4df3ddf11c38",
   "metadata": {},
   "outputs": [
    {
     "name": "stderr",
     "output_type": "stream",
     "text": [
      "C:\\Users\\10011\\anaconda3\\envs\\python_for_data_analysis\\lib\\site-packages\\sklearn\\utils\\deprecation.py:87: FutureWarning:\n",
      "\n",
      "Function load_boston is deprecated; `load_boston` is deprecated in 1.0 and will be removed in 1.2.\n",
      "\n",
      "    The Boston housing prices dataset has an ethical problem. You can refer to\n",
      "    the documentation of this function for further details.\n",
      "\n",
      "    The scikit-learn maintainers therefore strongly discourage the use of this\n",
      "    dataset unless the purpose of the code is to study and educate about\n",
      "    ethical issues in data science and machine learning.\n",
      "\n",
      "    In this special case, you can fetch the dataset from the original\n",
      "    source::\n",
      "\n",
      "        import pandas as pd\n",
      "        import numpy as np\n",
      "\n",
      "\n",
      "        data_url = \"http://lib.stat.cmu.edu/datasets/boston\"\n",
      "        raw_df = pd.read_csv(data_url, sep=\"\\s+\", skiprows=22, header=None)\n",
      "        data = np.hstack([raw_df.values[::2, :], raw_df.values[1::2, :2]])\n",
      "        target = raw_df.values[1::2, 2]\n",
      "\n",
      "    Alternative datasets include the California housing dataset (i.e.\n",
      "    :func:`~sklearn.datasets.fetch_california_housing`) and the Ames housing\n",
      "    dataset. You can load the datasets as follows::\n",
      "\n",
      "        from sklearn.datasets import fetch_california_housing\n",
      "        housing = fetch_california_housing()\n",
      "\n",
      "    for the California housing dataset and::\n",
      "\n",
      "        from sklearn.datasets import fetch_openml\n",
      "        housing = fetch_openml(name=\"house_prices\", as_frame=True)\n",
      "\n",
      "    for the Ames housing dataset.\n",
      "    \n",
      "\n"
     ]
    }
   ],
   "source": [
    "data = load_boston()\n",
    "data_X = pd.DataFrame(data.data,columns=data.feature_names)\n",
    "data_y = pd.DataFrame(data.target,columns=['MEDV'])\n",
    "X_train, X_test, y_train, y_test = train_test_split(data_X,data_y,random_state=2022)\n",
    "\n",
    "models = {'Regression': linear_model.LinearRegression,\n",
    "          'Decision Tree': tree.DecisionTreeRegressor,\n",
    "          'k-NN': neighbors.KNeighborsRegressor}"
   ]
  },
  {
   "cell_type": "markdown",
   "id": "05f55949-d449-4a7b-b05a-60ee065374bf",
   "metadata": {},
   "source": [
    "# Dash排版 + callback實作"
   ]
  },
  {
   "cell_type": "code",
   "execution_count": 173,
   "id": "b2dd86ee-9767-4b73-9f15-7e259900fc52",
   "metadata": {},
   "outputs": [],
   "source": [
    "app = Dash(__name__)\n",
    "\n",
    "\n",
    "app.layout = html.Div(\n",
    "    [\n",
    "        dbc.Container(\n",
    "            [\n",
    "                html.H2(\"Predict Median value of owner-occupied homes in $1000's\"),\n",
    "                html.P(\"Select Model:\"),\n",
    "                dcc.Dropdown(\n",
    "                id='dropdown_value',\n",
    "                options=[\"Regression\", \"Decision Tree\", \"k-NN\"],\n",
    "                clearable=False),\n",
    "                html.Br(),\n",
    "                html.Br(),\n",
    "                html.H3('Prediction vs Actual'),\n",
    "                dcc.Graph(id='graph1'),\n",
    "                html.H3('Train vs Test'),\n",
    "                dcc.Graph(id='graph2')\n",
    "            ]\n",
    "        )\n",
    "    ]\n",
    ")\n",
    "\n",
    "@app.callback(\n",
    "    Output('graph1','figure'),\n",
    "    Output('graph2','figure'),\n",
    "    Input('dropdown_value','value'))\n",
    "\n",
    "def get_prediction_lineplot(model_name):\n",
    "    model = models[model_name]()\n",
    "    model.fit(X_train,y_train)\n",
    "\n",
    "    train_graph = X_train.copy()\n",
    "    train_graph['preds'] = model.predict(X_train)\n",
    "    train_graph['actual'] = y_train\n",
    "    \n",
    "    test_graph = X_test.copy()\n",
    "    test_graph['preds'] = model.predict(X_test)\n",
    "    test_graph['actual'] = y_test\n",
    "    \n",
    "    fig1 = px.scatter(train_graph,x='preds',y='actual',opacity=0.65,trendline=\"ols\",trendline_scope=\"overall\")\n",
    "\n",
    "    fig2 = go.Figure(\n",
    "    [\n",
    "        go.Scatter(x=train_graph['preds'], y=train_graph['actual'],name='train', mode='markers'),\n",
    "        go.Scatter(x=test_graph['preds'], y=test_graph['actual'],name='test', mode='markers')\n",
    "    ])\n",
    "    return fig1,fig2"
   ]
  },
  {
   "cell_type": "code",
   "execution_count": 180,
   "id": "4ec25335-e166-47cc-831b-cba1dc6b3d49",
   "metadata": {},
   "outputs": [
    {
     "name": "stdout",
     "output_type": "stream",
     "text": [
      "Dash is running on http://127.0.0.1:8050/\n",
      "\n",
      "Dash is running on http://127.0.0.1:8050/\n",
      "\n",
      "Dash is running on http://127.0.0.1:8050/\n",
      "\n",
      "Dash is running on http://127.0.0.1:8050/\n",
      "\n",
      "Dash is running on http://127.0.0.1:8050/\n",
      "\n",
      "Dash is running on http://127.0.0.1:8050/\n",
      "\n",
      "Dash is running on http://127.0.0.1:8050/\n",
      "\n",
      "Dash is running on http://127.0.0.1:8050/\n",
      "\n",
      "Dash is running on http://127.0.0.1:8050/\n",
      "\n",
      "Dash is running on http://127.0.0.1:8050/\n",
      "\n",
      "Dash is running on http://127.0.0.1:8050/\n",
      "\n",
      "Dash is running on http://127.0.0.1:8050/\n",
      "\n",
      "Dash is running on http://127.0.0.1:8050/\n",
      "\n",
      "Dash is running on http://127.0.0.1:8050/\n",
      "\n",
      "Dash is running on http://127.0.0.1:8050/\n",
      "\n",
      "Dash is running on http://127.0.0.1:8050/\n",
      "\n",
      "Dash is running on http://127.0.0.1:8050/\n",
      "\n",
      "Dash is running on http://127.0.0.1:8050/\n",
      "\n",
      "Dash is running on http://127.0.0.1:8050/\n",
      "\n",
      "Dash is running on http://127.0.0.1:8050/\n",
      "\n",
      "Dash is running on http://127.0.0.1:8050/\n",
      "\n",
      "Dash is running on http://127.0.0.1:8050/\n",
      "\n",
      "Dash is running on http://127.0.0.1:8050/\n",
      "\n",
      "Dash is running on http://127.0.0.1:8050/\n",
      "\n",
      "Dash is running on http://127.0.0.1:8050/\n",
      "\n",
      "Dash is running on http://127.0.0.1:8050/\n",
      "\n",
      "Dash is running on http://127.0.0.1:8050/\n",
      "\n",
      "Dash is running on http://127.0.0.1:8050/\n",
      "\n",
      "Dash is running on http://127.0.0.1:8050/\n",
      "\n",
      "Dash is running on http://127.0.0.1:8050/\n",
      "\n",
      "Dash is running on http://127.0.0.1:8050/\n",
      "\n",
      "Dash is running on http://127.0.0.1:8050/\n",
      "\n",
      "Dash is running on http://127.0.0.1:8050/\n",
      "\n",
      "Dash is running on http://127.0.0.1:8050/\n",
      "\n",
      "Dash is running on http://127.0.0.1:8050/\n",
      "\n"
     ]
    },
    {
     "name": "stderr",
     "output_type": "stream",
     "text": [
      "INFO:__main__:Dash is running on http://127.0.0.1:8050/\n",
      "\n"
     ]
    },
    {
     "name": "stdout",
     "output_type": "stream",
     "text": [
      " * Serving Flask app '__main__' (lazy loading)\n",
      " * Environment: production\n",
      "   WARNING: This is a development server. Do not use it in a production deployment.\n",
      "   Use a production WSGI server instead.\n",
      " * Debug mode: off\n"
     ]
    },
    {
     "name": "stderr",
     "output_type": "stream",
     "text": [
      " * Running on http://127.0.0.1:8050/ (Press CTRL+C to quit)\n",
      "INFO:werkzeug: * Running on http://127.0.0.1:8050/ (Press CTRL+C to quit)\n",
      "127.0.0.1 - - [29/Mar/2022 03:24:50] \"GET / HTTP/1.1\" 200 -\n",
      "INFO:werkzeug:127.0.0.1 - - [29/Mar/2022 03:24:50] \"GET / HTTP/1.1\" 200 -\n",
      "127.0.0.1 - - [29/Mar/2022 03:24:50] \"GET /assets/css/bootstrap.min.css?m=1647935570.6230385 HTTP/1.1\" 304 -\n",
      "INFO:werkzeug:127.0.0.1 - - [29/Mar/2022 03:24:50] \"\u001b[36mGET /assets/css/bootstrap.min.css?m=1647935570.6230385 HTTP/1.1\u001b[0m\" 304 -\n",
      "127.0.0.1 - - [29/Mar/2022 03:24:50] \"GET /_dash-dependencies HTTP/1.1\" 200 -\n",
      "INFO:werkzeug:127.0.0.1 - - [29/Mar/2022 03:24:50] \"GET /_dash-dependencies HTTP/1.1\" 200 -\n",
      "127.0.0.1 - - [29/Mar/2022 03:24:50] \"GET /_dash-layout HTTP/1.1\" 200 -\n",
      "INFO:werkzeug:127.0.0.1 - - [29/Mar/2022 03:24:50] \"GET /_dash-layout HTTP/1.1\" 200 -\n",
      "127.0.0.1 - - [29/Mar/2022 03:24:51] \"GET /_dash-component-suites/dash/dcc/async-dropdown.js HTTP/1.1\" 200 -\n",
      "INFO:werkzeug:127.0.0.1 - - [29/Mar/2022 03:24:51] \"GET /_dash-component-suites/dash/dcc/async-dropdown.js HTTP/1.1\" 200 -\n",
      "127.0.0.1 - - [29/Mar/2022 03:24:51] \"GET /_dash-component-suites/dash/dcc/async-graph.js HTTP/1.1\" 200 -\n",
      "INFO:werkzeug:127.0.0.1 - - [29/Mar/2022 03:24:51] \"GET /_dash-component-suites/dash/dcc/async-graph.js HTTP/1.1\" 200 -\n",
      "127.0.0.1 - - [29/Mar/2022 03:24:51] \"GET /_dash-component-suites/dash/dcc/async-plotlyjs.js HTTP/1.1\" 200 -\n",
      "INFO:werkzeug:127.0.0.1 - - [29/Mar/2022 03:24:51] \"GET /_dash-component-suites/dash/dcc/async-plotlyjs.js HTTP/1.1\" 200 -\n"
     ]
    },
    {
     "name": "stdout",
     "output_type": "stream",
     "text": [
      "Exception on /_dash-update-component [POST]\n",
      "Traceback (most recent call last):\n",
      "  File \"C:\\Users\\10011\\anaconda3\\envs\\python_for_data_analysis\\lib\\site-packages\\flask\\app.py\", line 2073, in wsgi_app\n",
      "    response = self.full_dispatch_request()\n",
      "  File \"C:\\Users\\10011\\anaconda3\\envs\\python_for_data_analysis\\lib\\site-packages\\flask\\app.py\", line 1518, in full_dispatch_request\n",
      "    rv = self.handle_user_exception(e)\n",
      "  File \"C:\\Users\\10011\\anaconda3\\envs\\python_for_data_analysis\\lib\\site-packages\\flask\\app.py\", line 1516, in full_dispatch_request\n",
      "    rv = self.dispatch_request()\n",
      "  File \"C:\\Users\\10011\\anaconda3\\envs\\python_for_data_analysis\\lib\\site-packages\\flask\\app.py\", line 1502, in dispatch_request\n",
      "    return self.ensure_sync(self.view_functions[rule.endpoint])(**req.view_args)\n",
      "  File \"C:\\Users\\10011\\anaconda3\\envs\\python_for_data_analysis\\lib\\site-packages\\dash\\dash.py\", line 1345, in dispatch\n",
      "    response.set_data(func(*args, outputs_list=outputs_list))\n",
      "  File \"C:\\Users\\10011\\anaconda3\\envs\\python_for_data_analysis\\lib\\site-packages\\dash\\_callback.py\", line 151, in add_context\n",
      "    output_value = func(*func_args, **func_kwargs)  # %% callback invoked %%\n",
      "  File \"<ipython-input-173-1ce2b5b6bbc8>\", line 31, in get_prediction_lineplot\n",
      "    model = models[model_name]()\n",
      "KeyError: None\n",
      "Exception on /_dash-update-component [POST]\n",
      "Traceback (most recent call last):\n",
      "  File \"C:\\Users\\10011\\anaconda3\\envs\\python_for_data_analysis\\lib\\site-packages\\flask\\app.py\", line 2073, in wsgi_app\n",
      "    response = self.full_dispatch_request()\n",
      "  File \"C:\\Users\\10011\\anaconda3\\envs\\python_for_data_analysis\\lib\\site-packages\\flask\\app.py\", line 1518, in full_dispatch_request\n",
      "    rv = self.handle_user_exception(e)\n",
      "  File \"C:\\Users\\10011\\anaconda3\\envs\\python_for_data_analysis\\lib\\site-packages\\flask\\app.py\", line 1516, in full_dispatch_request\n",
      "    rv = self.dispatch_request()\n",
      "  File \"C:\\Users\\10011\\anaconda3\\envs\\python_for_data_analysis\\lib\\site-packages\\flask\\app.py\", line 1502, in dispatch_request\n",
      "    return self.ensure_sync(self.view_functions[rule.endpoint])(**req.view_args)\n",
      "  File \"C:\\Users\\10011\\anaconda3\\envs\\python_for_data_analysis\\lib\\site-packages\\dash\\dash.py\", line 1345, in dispatch\n",
      "    response.set_data(func(*args, outputs_list=outputs_list))\n",
      "  File \"C:\\Users\\10011\\anaconda3\\envs\\python_for_data_analysis\\lib\\site-packages\\dash\\_callback.py\", line 151, in add_context\n",
      "    output_value = func(*func_args, **func_kwargs)  # %% callback invoked %%\n",
      "  File \"<ipython-input-173-1ce2b5b6bbc8>\", line 31, in get_prediction_lineplot\n",
      "    model = models[model_name]()\n",
      "KeyError: None\n",
      "Exception on /_dash-update-component [POST]\n",
      "Traceback (most recent call last):\n",
      "  File \"C:\\Users\\10011\\anaconda3\\envs\\python_for_data_analysis\\lib\\site-packages\\flask\\app.py\", line 2073, in wsgi_app\n",
      "    response = self.full_dispatch_request()\n",
      "  File \"C:\\Users\\10011\\anaconda3\\envs\\python_for_data_analysis\\lib\\site-packages\\flask\\app.py\", line 1518, in full_dispatch_request\n",
      "    rv = self.handle_user_exception(e)\n",
      "  File \"C:\\Users\\10011\\anaconda3\\envs\\python_for_data_analysis\\lib\\site-packages\\flask\\app.py\", line 1516, in full_dispatch_request\n",
      "    rv = self.dispatch_request()\n",
      "  File \"C:\\Users\\10011\\anaconda3\\envs\\python_for_data_analysis\\lib\\site-packages\\flask\\app.py\", line 1502, in dispatch_request\n",
      "    return self.ensure_sync(self.view_functions[rule.endpoint])(**req.view_args)\n",
      "  File \"C:\\Users\\10011\\anaconda3\\envs\\python_for_data_analysis\\lib\\site-packages\\dash\\dash.py\", line 1345, in dispatch\n",
      "    response.set_data(func(*args, outputs_list=outputs_list))\n",
      "  File \"C:\\Users\\10011\\anaconda3\\envs\\python_for_data_analysis\\lib\\site-packages\\dash\\_callback.py\", line 151, in add_context\n",
      "    output_value = func(*func_args, **func_kwargs)  # %% callback invoked %%\n",
      "  File \"<ipython-input-173-1ce2b5b6bbc8>\", line 31, in get_prediction_lineplot\n",
      "    model = models[model_name]()\n",
      "KeyError: None\n",
      "Exception on /_dash-update-component [POST]\n",
      "Traceback (most recent call last):\n",
      "  File \"C:\\Users\\10011\\anaconda3\\envs\\python_for_data_analysis\\lib\\site-packages\\flask\\app.py\", line 2073, in wsgi_app\n",
      "    response = self.full_dispatch_request()\n",
      "  File \"C:\\Users\\10011\\anaconda3\\envs\\python_for_data_analysis\\lib\\site-packages\\flask\\app.py\", line 1518, in full_dispatch_request\n",
      "    rv = self.handle_user_exception(e)\n",
      "  File \"C:\\Users\\10011\\anaconda3\\envs\\python_for_data_analysis\\lib\\site-packages\\flask\\app.py\", line 1516, in full_dispatch_request\n",
      "    rv = self.dispatch_request()\n",
      "  File \"C:\\Users\\10011\\anaconda3\\envs\\python_for_data_analysis\\lib\\site-packages\\flask\\app.py\", line 1502, in dispatch_request\n",
      "    return self.ensure_sync(self.view_functions[rule.endpoint])(**req.view_args)\n",
      "  File \"C:\\Users\\10011\\anaconda3\\envs\\python_for_data_analysis\\lib\\site-packages\\dash\\dash.py\", line 1345, in dispatch\n",
      "    response.set_data(func(*args, outputs_list=outputs_list))\n",
      "  File \"C:\\Users\\10011\\anaconda3\\envs\\python_for_data_analysis\\lib\\site-packages\\dash\\_callback.py\", line 151, in add_context\n",
      "    output_value = func(*func_args, **func_kwargs)  # %% callback invoked %%\n",
      "  File \"<ipython-input-173-1ce2b5b6bbc8>\", line 31, in get_prediction_lineplot\n",
      "    model = models[model_name]()\n",
      "KeyError: None\n",
      "Exception on /_dash-update-component [POST]\n",
      "Traceback (most recent call last):\n",
      "  File \"C:\\Users\\10011\\anaconda3\\envs\\python_for_data_analysis\\lib\\site-packages\\flask\\app.py\", line 2073, in wsgi_app\n",
      "    response = self.full_dispatch_request()\n",
      "  File \"C:\\Users\\10011\\anaconda3\\envs\\python_for_data_analysis\\lib\\site-packages\\flask\\app.py\", line 1518, in full_dispatch_request\n",
      "    rv = self.handle_user_exception(e)\n",
      "  File \"C:\\Users\\10011\\anaconda3\\envs\\python_for_data_analysis\\lib\\site-packages\\flask\\app.py\", line 1516, in full_dispatch_request\n",
      "    rv = self.dispatch_request()\n",
      "  File \"C:\\Users\\10011\\anaconda3\\envs\\python_for_data_analysis\\lib\\site-packages\\flask\\app.py\", line 1502, in dispatch_request\n",
      "    return self.ensure_sync(self.view_functions[rule.endpoint])(**req.view_args)\n",
      "  File \"C:\\Users\\10011\\anaconda3\\envs\\python_for_data_analysis\\lib\\site-packages\\dash\\dash.py\", line 1345, in dispatch\n",
      "    response.set_data(func(*args, outputs_list=outputs_list))\n",
      "  File \"C:\\Users\\10011\\anaconda3\\envs\\python_for_data_analysis\\lib\\site-packages\\dash\\_callback.py\", line 151, in add_context\n",
      "    output_value = func(*func_args, **func_kwargs)  # %% callback invoked %%\n",
      "  File \"<ipython-input-173-1ce2b5b6bbc8>\", line 31, in get_prediction_lineplot\n",
      "    model = models[model_name]()\n",
      "KeyError: None\n",
      "Exception on /_dash-update-component [POST]\n",
      "Traceback (most recent call last):\n",
      "  File \"C:\\Users\\10011\\anaconda3\\envs\\python_for_data_analysis\\lib\\site-packages\\flask\\app.py\", line 2073, in wsgi_app\n",
      "    response = self.full_dispatch_request()\n",
      "  File \"C:\\Users\\10011\\anaconda3\\envs\\python_for_data_analysis\\lib\\site-packages\\flask\\app.py\", line 1518, in full_dispatch_request\n",
      "    rv = self.handle_user_exception(e)\n",
      "  File \"C:\\Users\\10011\\anaconda3\\envs\\python_for_data_analysis\\lib\\site-packages\\flask\\app.py\", line 1516, in full_dispatch_request\n",
      "    rv = self.dispatch_request()\n",
      "  File \"C:\\Users\\10011\\anaconda3\\envs\\python_for_data_analysis\\lib\\site-packages\\flask\\app.py\", line 1502, in dispatch_request\n",
      "    return self.ensure_sync(self.view_functions[rule.endpoint])(**req.view_args)\n",
      "  File \"C:\\Users\\10011\\anaconda3\\envs\\python_for_data_analysis\\lib\\site-packages\\dash\\dash.py\", line 1345, in dispatch\n",
      "    response.set_data(func(*args, outputs_list=outputs_list))\n",
      "  File \"C:\\Users\\10011\\anaconda3\\envs\\python_for_data_analysis\\lib\\site-packages\\dash\\_callback.py\", line 151, in add_context\n",
      "    output_value = func(*func_args, **func_kwargs)  # %% callback invoked %%\n",
      "  File \"<ipython-input-173-1ce2b5b6bbc8>\", line 31, in get_prediction_lineplot\n",
      "    model = models[model_name]()\n",
      "KeyError: None\n",
      "Exception on /_dash-update-component [POST]\n",
      "Traceback (most recent call last):\n",
      "  File \"C:\\Users\\10011\\anaconda3\\envs\\python_for_data_analysis\\lib\\site-packages\\flask\\app.py\", line 2073, in wsgi_app\n",
      "    response = self.full_dispatch_request()\n",
      "  File \"C:\\Users\\10011\\anaconda3\\envs\\python_for_data_analysis\\lib\\site-packages\\flask\\app.py\", line 1518, in full_dispatch_request\n",
      "    rv = self.handle_user_exception(e)\n",
      "  File \"C:\\Users\\10011\\anaconda3\\envs\\python_for_data_analysis\\lib\\site-packages\\flask\\app.py\", line 1516, in full_dispatch_request\n",
      "    rv = self.dispatch_request()\n",
      "  File \"C:\\Users\\10011\\anaconda3\\envs\\python_for_data_analysis\\lib\\site-packages\\flask\\app.py\", line 1502, in dispatch_request\n",
      "    return self.ensure_sync(self.view_functions[rule.endpoint])(**req.view_args)\n",
      "  File \"C:\\Users\\10011\\anaconda3\\envs\\python_for_data_analysis\\lib\\site-packages\\dash\\dash.py\", line 1345, in dispatch\n",
      "    response.set_data(func(*args, outputs_list=outputs_list))\n",
      "  File \"C:\\Users\\10011\\anaconda3\\envs\\python_for_data_analysis\\lib\\site-packages\\dash\\_callback.py\", line 151, in add_context\n",
      "    output_value = func(*func_args, **func_kwargs)  # %% callback invoked %%\n",
      "  File \"<ipython-input-173-1ce2b5b6bbc8>\", line 31, in get_prediction_lineplot\n",
      "    model = models[model_name]()\n",
      "KeyError: None\n",
      "Exception on /_dash-update-component [POST]\n",
      "Traceback (most recent call last):\n",
      "  File \"C:\\Users\\10011\\anaconda3\\envs\\python_for_data_analysis\\lib\\site-packages\\flask\\app.py\", line 2073, in wsgi_app\n",
      "    response = self.full_dispatch_request()\n",
      "  File \"C:\\Users\\10011\\anaconda3\\envs\\python_for_data_analysis\\lib\\site-packages\\flask\\app.py\", line 1518, in full_dispatch_request\n",
      "    rv = self.handle_user_exception(e)\n",
      "  File \"C:\\Users\\10011\\anaconda3\\envs\\python_for_data_analysis\\lib\\site-packages\\flask\\app.py\", line 1516, in full_dispatch_request\n",
      "    rv = self.dispatch_request()\n",
      "  File \"C:\\Users\\10011\\anaconda3\\envs\\python_for_data_analysis\\lib\\site-packages\\flask\\app.py\", line 1502, in dispatch_request\n",
      "    return self.ensure_sync(self.view_functions[rule.endpoint])(**req.view_args)\n",
      "  File \"C:\\Users\\10011\\anaconda3\\envs\\python_for_data_analysis\\lib\\site-packages\\dash\\dash.py\", line 1345, in dispatch\n",
      "    response.set_data(func(*args, outputs_list=outputs_list))\n",
      "  File \"C:\\Users\\10011\\anaconda3\\envs\\python_for_data_analysis\\lib\\site-packages\\dash\\_callback.py\", line 151, in add_context\n",
      "    output_value = func(*func_args, **func_kwargs)  # %% callback invoked %%\n",
      "  File \"<ipython-input-173-1ce2b5b6bbc8>\", line 31, in get_prediction_lineplot\n",
      "    model = models[model_name]()\n",
      "KeyError: None\n",
      "Exception on /_dash-update-component [POST]\n",
      "Traceback (most recent call last):\n",
      "  File \"C:\\Users\\10011\\anaconda3\\envs\\python_for_data_analysis\\lib\\site-packages\\flask\\app.py\", line 2073, in wsgi_app\n",
      "    response = self.full_dispatch_request()\n",
      "  File \"C:\\Users\\10011\\anaconda3\\envs\\python_for_data_analysis\\lib\\site-packages\\flask\\app.py\", line 1518, in full_dispatch_request\n",
      "    rv = self.handle_user_exception(e)\n",
      "  File \"C:\\Users\\10011\\anaconda3\\envs\\python_for_data_analysis\\lib\\site-packages\\flask\\app.py\", line 1516, in full_dispatch_request\n",
      "    rv = self.dispatch_request()\n",
      "  File \"C:\\Users\\10011\\anaconda3\\envs\\python_for_data_analysis\\lib\\site-packages\\flask\\app.py\", line 1502, in dispatch_request\n",
      "    return self.ensure_sync(self.view_functions[rule.endpoint])(**req.view_args)\n",
      "  File \"C:\\Users\\10011\\anaconda3\\envs\\python_for_data_analysis\\lib\\site-packages\\dash\\dash.py\", line 1345, in dispatch\n",
      "    response.set_data(func(*args, outputs_list=outputs_list))\n",
      "  File \"C:\\Users\\10011\\anaconda3\\envs\\python_for_data_analysis\\lib\\site-packages\\dash\\_callback.py\", line 151, in add_context\n",
      "    output_value = func(*func_args, **func_kwargs)  # %% callback invoked %%\n",
      "  File \"<ipython-input-173-1ce2b5b6bbc8>\", line 31, in get_prediction_lineplot\n",
      "    model = models[model_name]()\n",
      "KeyError: None\n",
      "Exception on /_dash-update-component [POST]\n",
      "Traceback (most recent call last):\n",
      "  File \"C:\\Users\\10011\\anaconda3\\envs\\python_for_data_analysis\\lib\\site-packages\\flask\\app.py\", line 2073, in wsgi_app\n",
      "    response = self.full_dispatch_request()\n",
      "  File \"C:\\Users\\10011\\anaconda3\\envs\\python_for_data_analysis\\lib\\site-packages\\flask\\app.py\", line 1518, in full_dispatch_request\n",
      "    rv = self.handle_user_exception(e)\n",
      "  File \"C:\\Users\\10011\\anaconda3\\envs\\python_for_data_analysis\\lib\\site-packages\\flask\\app.py\", line 1516, in full_dispatch_request\n",
      "    rv = self.dispatch_request()\n",
      "  File \"C:\\Users\\10011\\anaconda3\\envs\\python_for_data_analysis\\lib\\site-packages\\flask\\app.py\", line 1502, in dispatch_request\n",
      "    return self.ensure_sync(self.view_functions[rule.endpoint])(**req.view_args)\n",
      "  File \"C:\\Users\\10011\\anaconda3\\envs\\python_for_data_analysis\\lib\\site-packages\\dash\\dash.py\", line 1345, in dispatch\n",
      "    response.set_data(func(*args, outputs_list=outputs_list))\n",
      "  File \"C:\\Users\\10011\\anaconda3\\envs\\python_for_data_analysis\\lib\\site-packages\\dash\\_callback.py\", line 151, in add_context\n",
      "    output_value = func(*func_args, **func_kwargs)  # %% callback invoked %%\n",
      "  File \"<ipython-input-173-1ce2b5b6bbc8>\", line 31, in get_prediction_lineplot\n",
      "    model = models[model_name]()\n",
      "KeyError: None\n",
      "Exception on /_dash-update-component [POST]\n",
      "Traceback (most recent call last):\n",
      "  File \"C:\\Users\\10011\\anaconda3\\envs\\python_for_data_analysis\\lib\\site-packages\\flask\\app.py\", line 2073, in wsgi_app\n",
      "    response = self.full_dispatch_request()\n",
      "  File \"C:\\Users\\10011\\anaconda3\\envs\\python_for_data_analysis\\lib\\site-packages\\flask\\app.py\", line 1518, in full_dispatch_request\n",
      "    rv = self.handle_user_exception(e)\n",
      "  File \"C:\\Users\\10011\\anaconda3\\envs\\python_for_data_analysis\\lib\\site-packages\\flask\\app.py\", line 1516, in full_dispatch_request\n",
      "    rv = self.dispatch_request()\n",
      "  File \"C:\\Users\\10011\\anaconda3\\envs\\python_for_data_analysis\\lib\\site-packages\\flask\\app.py\", line 1502, in dispatch_request\n",
      "    return self.ensure_sync(self.view_functions[rule.endpoint])(**req.view_args)\n",
      "  File \"C:\\Users\\10011\\anaconda3\\envs\\python_for_data_analysis\\lib\\site-packages\\dash\\dash.py\", line 1345, in dispatch\n",
      "    response.set_data(func(*args, outputs_list=outputs_list))\n",
      "  File \"C:\\Users\\10011\\anaconda3\\envs\\python_for_data_analysis\\lib\\site-packages\\dash\\_callback.py\", line 151, in add_context\n",
      "    output_value = func(*func_args, **func_kwargs)  # %% callback invoked %%\n",
      "  File \"<ipython-input-173-1ce2b5b6bbc8>\", line 31, in get_prediction_lineplot\n",
      "    model = models[model_name]()\n",
      "KeyError: None\n",
      "Exception on /_dash-update-component [POST]\n",
      "Traceback (most recent call last):\n",
      "  File \"C:\\Users\\10011\\anaconda3\\envs\\python_for_data_analysis\\lib\\site-packages\\flask\\app.py\", line 2073, in wsgi_app\n",
      "    response = self.full_dispatch_request()\n",
      "  File \"C:\\Users\\10011\\anaconda3\\envs\\python_for_data_analysis\\lib\\site-packages\\flask\\app.py\", line 1518, in full_dispatch_request\n",
      "    rv = self.handle_user_exception(e)\n",
      "  File \"C:\\Users\\10011\\anaconda3\\envs\\python_for_data_analysis\\lib\\site-packages\\flask\\app.py\", line 1516, in full_dispatch_request\n",
      "    rv = self.dispatch_request()\n",
      "  File \"C:\\Users\\10011\\anaconda3\\envs\\python_for_data_analysis\\lib\\site-packages\\flask\\app.py\", line 1502, in dispatch_request\n",
      "    return self.ensure_sync(self.view_functions[rule.endpoint])(**req.view_args)\n",
      "  File \"C:\\Users\\10011\\anaconda3\\envs\\python_for_data_analysis\\lib\\site-packages\\dash\\dash.py\", line 1345, in dispatch\n",
      "    response.set_data(func(*args, outputs_list=outputs_list))\n",
      "  File \"C:\\Users\\10011\\anaconda3\\envs\\python_for_data_analysis\\lib\\site-packages\\dash\\_callback.py\", line 151, in add_context\n",
      "    output_value = func(*func_args, **func_kwargs)  # %% callback invoked %%\n",
      "  File \"<ipython-input-173-1ce2b5b6bbc8>\", line 31, in get_prediction_lineplot\n",
      "    model = models[model_name]()\n",
      "KeyError: None\n",
      "Exception on /_dash-update-component [POST]\n",
      "Traceback (most recent call last):\n",
      "  File \"C:\\Users\\10011\\anaconda3\\envs\\python_for_data_analysis\\lib\\site-packages\\flask\\app.py\", line 2073, in wsgi_app\n",
      "    response = self.full_dispatch_request()\n",
      "  File \"C:\\Users\\10011\\anaconda3\\envs\\python_for_data_analysis\\lib\\site-packages\\flask\\app.py\", line 1518, in full_dispatch_request\n",
      "    rv = self.handle_user_exception(e)\n",
      "  File \"C:\\Users\\10011\\anaconda3\\envs\\python_for_data_analysis\\lib\\site-packages\\flask\\app.py\", line 1516, in full_dispatch_request\n",
      "    rv = self.dispatch_request()\n",
      "  File \"C:\\Users\\10011\\anaconda3\\envs\\python_for_data_analysis\\lib\\site-packages\\flask\\app.py\", line 1502, in dispatch_request\n",
      "    return self.ensure_sync(self.view_functions[rule.endpoint])(**req.view_args)\n",
      "  File \"C:\\Users\\10011\\anaconda3\\envs\\python_for_data_analysis\\lib\\site-packages\\dash\\dash.py\", line 1345, in dispatch\n",
      "    response.set_data(func(*args, outputs_list=outputs_list))\n",
      "  File \"C:\\Users\\10011\\anaconda3\\envs\\python_for_data_analysis\\lib\\site-packages\\dash\\_callback.py\", line 151, in add_context\n",
      "    output_value = func(*func_args, **func_kwargs)  # %% callback invoked %%\n",
      "  File \"<ipython-input-173-1ce2b5b6bbc8>\", line 31, in get_prediction_lineplot\n",
      "    model = models[model_name]()\n",
      "KeyError: None\n",
      "Exception on /_dash-update-component [POST]\n",
      "Traceback (most recent call last):\n",
      "  File \"C:\\Users\\10011\\anaconda3\\envs\\python_for_data_analysis\\lib\\site-packages\\flask\\app.py\", line 2073, in wsgi_app\n",
      "    response = self.full_dispatch_request()\n",
      "  File \"C:\\Users\\10011\\anaconda3\\envs\\python_for_data_analysis\\lib\\site-packages\\flask\\app.py\", line 1518, in full_dispatch_request\n",
      "    rv = self.handle_user_exception(e)\n",
      "  File \"C:\\Users\\10011\\anaconda3\\envs\\python_for_data_analysis\\lib\\site-packages\\flask\\app.py\", line 1516, in full_dispatch_request\n",
      "    rv = self.dispatch_request()\n",
      "  File \"C:\\Users\\10011\\anaconda3\\envs\\python_for_data_analysis\\lib\\site-packages\\flask\\app.py\", line 1502, in dispatch_request\n",
      "    return self.ensure_sync(self.view_functions[rule.endpoint])(**req.view_args)\n",
      "  File \"C:\\Users\\10011\\anaconda3\\envs\\python_for_data_analysis\\lib\\site-packages\\dash\\dash.py\", line 1345, in dispatch\n",
      "    response.set_data(func(*args, outputs_list=outputs_list))\n",
      "  File \"C:\\Users\\10011\\anaconda3\\envs\\python_for_data_analysis\\lib\\site-packages\\dash\\_callback.py\", line 151, in add_context\n",
      "    output_value = func(*func_args, **func_kwargs)  # %% callback invoked %%\n",
      "  File \"<ipython-input-173-1ce2b5b6bbc8>\", line 31, in get_prediction_lineplot\n",
      "    model = models[model_name]()\n",
      "KeyError: None\n",
      "Exception on /_dash-update-component [POST]\n",
      "Traceback (most recent call last):\n",
      "  File \"C:\\Users\\10011\\anaconda3\\envs\\python_for_data_analysis\\lib\\site-packages\\flask\\app.py\", line 2073, in wsgi_app\n",
      "    response = self.full_dispatch_request()\n",
      "  File \"C:\\Users\\10011\\anaconda3\\envs\\python_for_data_analysis\\lib\\site-packages\\flask\\app.py\", line 1518, in full_dispatch_request\n",
      "    rv = self.handle_user_exception(e)\n",
      "  File \"C:\\Users\\10011\\anaconda3\\envs\\python_for_data_analysis\\lib\\site-packages\\flask\\app.py\", line 1516, in full_dispatch_request\n",
      "    rv = self.dispatch_request()\n",
      "  File \"C:\\Users\\10011\\anaconda3\\envs\\python_for_data_analysis\\lib\\site-packages\\flask\\app.py\", line 1502, in dispatch_request\n",
      "    return self.ensure_sync(self.view_functions[rule.endpoint])(**req.view_args)\n",
      "  File \"C:\\Users\\10011\\anaconda3\\envs\\python_for_data_analysis\\lib\\site-packages\\dash\\dash.py\", line 1345, in dispatch\n",
      "    response.set_data(func(*args, outputs_list=outputs_list))\n",
      "  File \"C:\\Users\\10011\\anaconda3\\envs\\python_for_data_analysis\\lib\\site-packages\\dash\\_callback.py\", line 151, in add_context\n",
      "    output_value = func(*func_args, **func_kwargs)  # %% callback invoked %%\n",
      "  File \"<ipython-input-173-1ce2b5b6bbc8>\", line 31, in get_prediction_lineplot\n",
      "    model = models[model_name]()\n",
      "KeyError: None\n",
      "Exception on /_dash-update-component [POST]\n",
      "Traceback (most recent call last):\n",
      "  File \"C:\\Users\\10011\\anaconda3\\envs\\python_for_data_analysis\\lib\\site-packages\\flask\\app.py\", line 2073, in wsgi_app\n",
      "    response = self.full_dispatch_request()\n",
      "  File \"C:\\Users\\10011\\anaconda3\\envs\\python_for_data_analysis\\lib\\site-packages\\flask\\app.py\", line 1518, in full_dispatch_request\n",
      "    rv = self.handle_user_exception(e)\n",
      "  File \"C:\\Users\\10011\\anaconda3\\envs\\python_for_data_analysis\\lib\\site-packages\\flask\\app.py\", line 1516, in full_dispatch_request\n",
      "    rv = self.dispatch_request()\n",
      "  File \"C:\\Users\\10011\\anaconda3\\envs\\python_for_data_analysis\\lib\\site-packages\\flask\\app.py\", line 1502, in dispatch_request\n",
      "    return self.ensure_sync(self.view_functions[rule.endpoint])(**req.view_args)\n",
      "  File \"C:\\Users\\10011\\anaconda3\\envs\\python_for_data_analysis\\lib\\site-packages\\dash\\dash.py\", line 1345, in dispatch\n",
      "    response.set_data(func(*args, outputs_list=outputs_list))\n",
      "  File \"C:\\Users\\10011\\anaconda3\\envs\\python_for_data_analysis\\lib\\site-packages\\dash\\_callback.py\", line 151, in add_context\n",
      "    output_value = func(*func_args, **func_kwargs)  # %% callback invoked %%\n",
      "  File \"<ipython-input-173-1ce2b5b6bbc8>\", line 31, in get_prediction_lineplot\n",
      "    model = models[model_name]()\n",
      "KeyError: None\n",
      "Exception on /_dash-update-component [POST]\n",
      "Traceback (most recent call last):\n",
      "  File \"C:\\Users\\10011\\anaconda3\\envs\\python_for_data_analysis\\lib\\site-packages\\flask\\app.py\", line 2073, in wsgi_app\n",
      "    response = self.full_dispatch_request()\n",
      "  File \"C:\\Users\\10011\\anaconda3\\envs\\python_for_data_analysis\\lib\\site-packages\\flask\\app.py\", line 1518, in full_dispatch_request\n",
      "    rv = self.handle_user_exception(e)\n",
      "  File \"C:\\Users\\10011\\anaconda3\\envs\\python_for_data_analysis\\lib\\site-packages\\flask\\app.py\", line 1516, in full_dispatch_request\n",
      "    rv = self.dispatch_request()\n",
      "  File \"C:\\Users\\10011\\anaconda3\\envs\\python_for_data_analysis\\lib\\site-packages\\flask\\app.py\", line 1502, in dispatch_request\n",
      "    return self.ensure_sync(self.view_functions[rule.endpoint])(**req.view_args)\n",
      "  File \"C:\\Users\\10011\\anaconda3\\envs\\python_for_data_analysis\\lib\\site-packages\\dash\\dash.py\", line 1345, in dispatch\n",
      "    response.set_data(func(*args, outputs_list=outputs_list))\n",
      "  File \"C:\\Users\\10011\\anaconda3\\envs\\python_for_data_analysis\\lib\\site-packages\\dash\\_callback.py\", line 151, in add_context\n",
      "    output_value = func(*func_args, **func_kwargs)  # %% callback invoked %%\n",
      "  File \"<ipython-input-173-1ce2b5b6bbc8>\", line 31, in get_prediction_lineplot\n",
      "    model = models[model_name]()\n",
      "KeyError: None\n",
      "Exception on /_dash-update-component [POST]\n",
      "Traceback (most recent call last):\n",
      "  File \"C:\\Users\\10011\\anaconda3\\envs\\python_for_data_analysis\\lib\\site-packages\\flask\\app.py\", line 2073, in wsgi_app\n",
      "    response = self.full_dispatch_request()\n",
      "  File \"C:\\Users\\10011\\anaconda3\\envs\\python_for_data_analysis\\lib\\site-packages\\flask\\app.py\", line 1518, in full_dispatch_request\n",
      "    rv = self.handle_user_exception(e)\n",
      "  File \"C:\\Users\\10011\\anaconda3\\envs\\python_for_data_analysis\\lib\\site-packages\\flask\\app.py\", line 1516, in full_dispatch_request\n",
      "    rv = self.dispatch_request()\n",
      "  File \"C:\\Users\\10011\\anaconda3\\envs\\python_for_data_analysis\\lib\\site-packages\\flask\\app.py\", line 1502, in dispatch_request\n",
      "    return self.ensure_sync(self.view_functions[rule.endpoint])(**req.view_args)\n",
      "  File \"C:\\Users\\10011\\anaconda3\\envs\\python_for_data_analysis\\lib\\site-packages\\dash\\dash.py\", line 1345, in dispatch\n",
      "    response.set_data(func(*args, outputs_list=outputs_list))\n",
      "  File \"C:\\Users\\10011\\anaconda3\\envs\\python_for_data_analysis\\lib\\site-packages\\dash\\_callback.py\", line 151, in add_context\n",
      "    output_value = func(*func_args, **func_kwargs)  # %% callback invoked %%\n",
      "  File \"<ipython-input-173-1ce2b5b6bbc8>\", line 31, in get_prediction_lineplot\n",
      "    model = models[model_name]()\n",
      "KeyError: None\n",
      "Exception on /_dash-update-component [POST]\n",
      "Traceback (most recent call last):\n",
      "  File \"C:\\Users\\10011\\anaconda3\\envs\\python_for_data_analysis\\lib\\site-packages\\flask\\app.py\", line 2073, in wsgi_app\n",
      "    response = self.full_dispatch_request()\n",
      "  File \"C:\\Users\\10011\\anaconda3\\envs\\python_for_data_analysis\\lib\\site-packages\\flask\\app.py\", line 1518, in full_dispatch_request\n",
      "    rv = self.handle_user_exception(e)\n",
      "  File \"C:\\Users\\10011\\anaconda3\\envs\\python_for_data_analysis\\lib\\site-packages\\flask\\app.py\", line 1516, in full_dispatch_request\n",
      "    rv = self.dispatch_request()\n",
      "  File \"C:\\Users\\10011\\anaconda3\\envs\\python_for_data_analysis\\lib\\site-packages\\flask\\app.py\", line 1502, in dispatch_request\n",
      "    return self.ensure_sync(self.view_functions[rule.endpoint])(**req.view_args)\n",
      "  File \"C:\\Users\\10011\\anaconda3\\envs\\python_for_data_analysis\\lib\\site-packages\\dash\\dash.py\", line 1345, in dispatch\n",
      "    response.set_data(func(*args, outputs_list=outputs_list))\n",
      "  File \"C:\\Users\\10011\\anaconda3\\envs\\python_for_data_analysis\\lib\\site-packages\\dash\\_callback.py\", line 151, in add_context\n",
      "    output_value = func(*func_args, **func_kwargs)  # %% callback invoked %%\n",
      "  File \"<ipython-input-173-1ce2b5b6bbc8>\", line 31, in get_prediction_lineplot\n",
      "    model = models[model_name]()\n",
      "KeyError: None\n",
      "Exception on /_dash-update-component [POST]\n",
      "Traceback (most recent call last):\n",
      "  File \"C:\\Users\\10011\\anaconda3\\envs\\python_for_data_analysis\\lib\\site-packages\\flask\\app.py\", line 2073, in wsgi_app\n",
      "    response = self.full_dispatch_request()\n",
      "  File \"C:\\Users\\10011\\anaconda3\\envs\\python_for_data_analysis\\lib\\site-packages\\flask\\app.py\", line 1518, in full_dispatch_request\n",
      "    rv = self.handle_user_exception(e)\n",
      "  File \"C:\\Users\\10011\\anaconda3\\envs\\python_for_data_analysis\\lib\\site-packages\\flask\\app.py\", line 1516, in full_dispatch_request\n",
      "    rv = self.dispatch_request()\n",
      "  File \"C:\\Users\\10011\\anaconda3\\envs\\python_for_data_analysis\\lib\\site-packages\\flask\\app.py\", line 1502, in dispatch_request\n",
      "    return self.ensure_sync(self.view_functions[rule.endpoint])(**req.view_args)\n",
      "  File \"C:\\Users\\10011\\anaconda3\\envs\\python_for_data_analysis\\lib\\site-packages\\dash\\dash.py\", line 1345, in dispatch\n",
      "    response.set_data(func(*args, outputs_list=outputs_list))\n",
      "  File \"C:\\Users\\10011\\anaconda3\\envs\\python_for_data_analysis\\lib\\site-packages\\dash\\_callback.py\", line 151, in add_context\n",
      "    output_value = func(*func_args, **func_kwargs)  # %% callback invoked %%\n",
      "  File \"<ipython-input-173-1ce2b5b6bbc8>\", line 31, in get_prediction_lineplot\n",
      "    model = models[model_name]()\n",
      "KeyError: None\n",
      "Exception on /_dash-update-component [POST]\n",
      "Traceback (most recent call last):\n",
      "  File \"C:\\Users\\10011\\anaconda3\\envs\\python_for_data_analysis\\lib\\site-packages\\flask\\app.py\", line 2073, in wsgi_app\n",
      "    response = self.full_dispatch_request()\n",
      "  File \"C:\\Users\\10011\\anaconda3\\envs\\python_for_data_analysis\\lib\\site-packages\\flask\\app.py\", line 1518, in full_dispatch_request\n",
      "    rv = self.handle_user_exception(e)\n",
      "  File \"C:\\Users\\10011\\anaconda3\\envs\\python_for_data_analysis\\lib\\site-packages\\flask\\app.py\", line 1516, in full_dispatch_request\n",
      "    rv = self.dispatch_request()\n",
      "  File \"C:\\Users\\10011\\anaconda3\\envs\\python_for_data_analysis\\lib\\site-packages\\flask\\app.py\", line 1502, in dispatch_request\n",
      "    return self.ensure_sync(self.view_functions[rule.endpoint])(**req.view_args)\n",
      "  File \"C:\\Users\\10011\\anaconda3\\envs\\python_for_data_analysis\\lib\\site-packages\\dash\\dash.py\", line 1345, in dispatch\n",
      "    response.set_data(func(*args, outputs_list=outputs_list))\n",
      "  File \"C:\\Users\\10011\\anaconda3\\envs\\python_for_data_analysis\\lib\\site-packages\\dash\\_callback.py\", line 151, in add_context\n",
      "    output_value = func(*func_args, **func_kwargs)  # %% callback invoked %%\n",
      "  File \"<ipython-input-173-1ce2b5b6bbc8>\", line 31, in get_prediction_lineplot\n",
      "    model = models[model_name]()\n",
      "KeyError: None\n",
      "Exception on /_dash-update-component [POST]\n",
      "Traceback (most recent call last):\n",
      "  File \"C:\\Users\\10011\\anaconda3\\envs\\python_for_data_analysis\\lib\\site-packages\\flask\\app.py\", line 2073, in wsgi_app\n",
      "    response = self.full_dispatch_request()\n",
      "  File \"C:\\Users\\10011\\anaconda3\\envs\\python_for_data_analysis\\lib\\site-packages\\flask\\app.py\", line 1518, in full_dispatch_request\n",
      "    rv = self.handle_user_exception(e)\n",
      "  File \"C:\\Users\\10011\\anaconda3\\envs\\python_for_data_analysis\\lib\\site-packages\\flask\\app.py\", line 1516, in full_dispatch_request\n",
      "    rv = self.dispatch_request()\n",
      "  File \"C:\\Users\\10011\\anaconda3\\envs\\python_for_data_analysis\\lib\\site-packages\\flask\\app.py\", line 1502, in dispatch_request\n",
      "    return self.ensure_sync(self.view_functions[rule.endpoint])(**req.view_args)\n",
      "  File \"C:\\Users\\10011\\anaconda3\\envs\\python_for_data_analysis\\lib\\site-packages\\dash\\dash.py\", line 1345, in dispatch\n",
      "    response.set_data(func(*args, outputs_list=outputs_list))\n",
      "  File \"C:\\Users\\10011\\anaconda3\\envs\\python_for_data_analysis\\lib\\site-packages\\dash\\_callback.py\", line 151, in add_context\n",
      "    output_value = func(*func_args, **func_kwargs)  # %% callback invoked %%\n",
      "  File \"<ipython-input-173-1ce2b5b6bbc8>\", line 31, in get_prediction_lineplot\n",
      "    model = models[model_name]()\n",
      "KeyError: None\n",
      "Exception on /_dash-update-component [POST]\n",
      "Traceback (most recent call last):\n",
      "  File \"C:\\Users\\10011\\anaconda3\\envs\\python_for_data_analysis\\lib\\site-packages\\flask\\app.py\", line 2073, in wsgi_app\n",
      "    response = self.full_dispatch_request()\n",
      "  File \"C:\\Users\\10011\\anaconda3\\envs\\python_for_data_analysis\\lib\\site-packages\\flask\\app.py\", line 1518, in full_dispatch_request\n",
      "    rv = self.handle_user_exception(e)\n",
      "  File \"C:\\Users\\10011\\anaconda3\\envs\\python_for_data_analysis\\lib\\site-packages\\flask\\app.py\", line 1516, in full_dispatch_request\n",
      "    rv = self.dispatch_request()\n",
      "  File \"C:\\Users\\10011\\anaconda3\\envs\\python_for_data_analysis\\lib\\site-packages\\flask\\app.py\", line 1502, in dispatch_request\n",
      "    return self.ensure_sync(self.view_functions[rule.endpoint])(**req.view_args)\n",
      "  File \"C:\\Users\\10011\\anaconda3\\envs\\python_for_data_analysis\\lib\\site-packages\\dash\\dash.py\", line 1345, in dispatch\n",
      "    response.set_data(func(*args, outputs_list=outputs_list))\n",
      "  File \"C:\\Users\\10011\\anaconda3\\envs\\python_for_data_analysis\\lib\\site-packages\\dash\\_callback.py\", line 151, in add_context\n",
      "    output_value = func(*func_args, **func_kwargs)  # %% callback invoked %%\n",
      "  File \"<ipython-input-173-1ce2b5b6bbc8>\", line 31, in get_prediction_lineplot\n",
      "    model = models[model_name]()\n",
      "KeyError: None\n",
      "Exception on /_dash-update-component [POST]\n",
      "Traceback (most recent call last):\n",
      "  File \"C:\\Users\\10011\\anaconda3\\envs\\python_for_data_analysis\\lib\\site-packages\\flask\\app.py\", line 2073, in wsgi_app\n",
      "    response = self.full_dispatch_request()\n",
      "  File \"C:\\Users\\10011\\anaconda3\\envs\\python_for_data_analysis\\lib\\site-packages\\flask\\app.py\", line 1518, in full_dispatch_request\n",
      "    rv = self.handle_user_exception(e)\n",
      "  File \"C:\\Users\\10011\\anaconda3\\envs\\python_for_data_analysis\\lib\\site-packages\\flask\\app.py\", line 1516, in full_dispatch_request\n",
      "    rv = self.dispatch_request()\n",
      "  File \"C:\\Users\\10011\\anaconda3\\envs\\python_for_data_analysis\\lib\\site-packages\\flask\\app.py\", line 1502, in dispatch_request\n",
      "    return self.ensure_sync(self.view_functions[rule.endpoint])(**req.view_args)\n",
      "  File \"C:\\Users\\10011\\anaconda3\\envs\\python_for_data_analysis\\lib\\site-packages\\dash\\dash.py\", line 1345, in dispatch\n",
      "    response.set_data(func(*args, outputs_list=outputs_list))\n",
      "  File \"C:\\Users\\10011\\anaconda3\\envs\\python_for_data_analysis\\lib\\site-packages\\dash\\_callback.py\", line 151, in add_context\n",
      "    output_value = func(*func_args, **func_kwargs)  # %% callback invoked %%\n",
      "  File \"<ipython-input-173-1ce2b5b6bbc8>\", line 31, in get_prediction_lineplot\n",
      "    model = models[model_name]()\n",
      "KeyError: None\n",
      "Exception on /_dash-update-component [POST]\n",
      "Traceback (most recent call last):\n",
      "  File \"C:\\Users\\10011\\anaconda3\\envs\\python_for_data_analysis\\lib\\site-packages\\flask\\app.py\", line 2073, in wsgi_app\n",
      "    response = self.full_dispatch_request()\n",
      "  File \"C:\\Users\\10011\\anaconda3\\envs\\python_for_data_analysis\\lib\\site-packages\\flask\\app.py\", line 1518, in full_dispatch_request\n",
      "    rv = self.handle_user_exception(e)\n",
      "  File \"C:\\Users\\10011\\anaconda3\\envs\\python_for_data_analysis\\lib\\site-packages\\flask\\app.py\", line 1516, in full_dispatch_request\n",
      "    rv = self.dispatch_request()\n",
      "  File \"C:\\Users\\10011\\anaconda3\\envs\\python_for_data_analysis\\lib\\site-packages\\flask\\app.py\", line 1502, in dispatch_request\n",
      "    return self.ensure_sync(self.view_functions[rule.endpoint])(**req.view_args)\n",
      "  File \"C:\\Users\\10011\\anaconda3\\envs\\python_for_data_analysis\\lib\\site-packages\\dash\\dash.py\", line 1345, in dispatch\n",
      "    response.set_data(func(*args, outputs_list=outputs_list))\n",
      "  File \"C:\\Users\\10011\\anaconda3\\envs\\python_for_data_analysis\\lib\\site-packages\\dash\\_callback.py\", line 151, in add_context\n",
      "    output_value = func(*func_args, **func_kwargs)  # %% callback invoked %%\n",
      "  File \"<ipython-input-173-1ce2b5b6bbc8>\", line 31, in get_prediction_lineplot\n",
      "    model = models[model_name]()\n",
      "KeyError: None\n",
      "Exception on /_dash-update-component [POST]\n",
      "Traceback (most recent call last):\n",
      "  File \"C:\\Users\\10011\\anaconda3\\envs\\python_for_data_analysis\\lib\\site-packages\\flask\\app.py\", line 2073, in wsgi_app\n",
      "    response = self.full_dispatch_request()\n",
      "  File \"C:\\Users\\10011\\anaconda3\\envs\\python_for_data_analysis\\lib\\site-packages\\flask\\app.py\", line 1518, in full_dispatch_request\n",
      "    rv = self.handle_user_exception(e)\n",
      "  File \"C:\\Users\\10011\\anaconda3\\envs\\python_for_data_analysis\\lib\\site-packages\\flask\\app.py\", line 1516, in full_dispatch_request\n",
      "    rv = self.dispatch_request()\n",
      "  File \"C:\\Users\\10011\\anaconda3\\envs\\python_for_data_analysis\\lib\\site-packages\\flask\\app.py\", line 1502, in dispatch_request\n",
      "    return self.ensure_sync(self.view_functions[rule.endpoint])(**req.view_args)\n",
      "  File \"C:\\Users\\10011\\anaconda3\\envs\\python_for_data_analysis\\lib\\site-packages\\dash\\dash.py\", line 1345, in dispatch\n",
      "    response.set_data(func(*args, outputs_list=outputs_list))\n",
      "  File \"C:\\Users\\10011\\anaconda3\\envs\\python_for_data_analysis\\lib\\site-packages\\dash\\_callback.py\", line 151, in add_context\n",
      "    output_value = func(*func_args, **func_kwargs)  # %% callback invoked %%\n",
      "  File \"<ipython-input-173-1ce2b5b6bbc8>\", line 31, in get_prediction_lineplot\n",
      "    model = models[model_name]()\n",
      "KeyError: None\n",
      "Exception on /_dash-update-component [POST]\n",
      "Traceback (most recent call last):\n",
      "  File \"C:\\Users\\10011\\anaconda3\\envs\\python_for_data_analysis\\lib\\site-packages\\flask\\app.py\", line 2073, in wsgi_app\n",
      "    response = self.full_dispatch_request()\n",
      "  File \"C:\\Users\\10011\\anaconda3\\envs\\python_for_data_analysis\\lib\\site-packages\\flask\\app.py\", line 1518, in full_dispatch_request\n",
      "    rv = self.handle_user_exception(e)\n",
      "  File \"C:\\Users\\10011\\anaconda3\\envs\\python_for_data_analysis\\lib\\site-packages\\flask\\app.py\", line 1516, in full_dispatch_request\n",
      "    rv = self.dispatch_request()\n",
      "  File \"C:\\Users\\10011\\anaconda3\\envs\\python_for_data_analysis\\lib\\site-packages\\flask\\app.py\", line 1502, in dispatch_request\n",
      "    return self.ensure_sync(self.view_functions[rule.endpoint])(**req.view_args)\n",
      "  File \"C:\\Users\\10011\\anaconda3\\envs\\python_for_data_analysis\\lib\\site-packages\\dash\\dash.py\", line 1345, in dispatch\n",
      "    response.set_data(func(*args, outputs_list=outputs_list))\n",
      "  File \"C:\\Users\\10011\\anaconda3\\envs\\python_for_data_analysis\\lib\\site-packages\\dash\\_callback.py\", line 151, in add_context\n",
      "    output_value = func(*func_args, **func_kwargs)  # %% callback invoked %%\n",
      "  File \"<ipython-input-173-1ce2b5b6bbc8>\", line 31, in get_prediction_lineplot\n",
      "    model = models[model_name]()\n",
      "KeyError: None\n",
      "Exception on /_dash-update-component [POST]\n",
      "Traceback (most recent call last):\n",
      "  File \"C:\\Users\\10011\\anaconda3\\envs\\python_for_data_analysis\\lib\\site-packages\\flask\\app.py\", line 2073, in wsgi_app\n",
      "    response = self.full_dispatch_request()\n",
      "  File \"C:\\Users\\10011\\anaconda3\\envs\\python_for_data_analysis\\lib\\site-packages\\flask\\app.py\", line 1518, in full_dispatch_request\n",
      "    rv = self.handle_user_exception(e)\n",
      "  File \"C:\\Users\\10011\\anaconda3\\envs\\python_for_data_analysis\\lib\\site-packages\\flask\\app.py\", line 1516, in full_dispatch_request\n",
      "    rv = self.dispatch_request()\n",
      "  File \"C:\\Users\\10011\\anaconda3\\envs\\python_for_data_analysis\\lib\\site-packages\\flask\\app.py\", line 1502, in dispatch_request\n",
      "    return self.ensure_sync(self.view_functions[rule.endpoint])(**req.view_args)\n",
      "  File \"C:\\Users\\10011\\anaconda3\\envs\\python_for_data_analysis\\lib\\site-packages\\dash\\dash.py\", line 1345, in dispatch\n",
      "    response.set_data(func(*args, outputs_list=outputs_list))\n",
      "  File \"C:\\Users\\10011\\anaconda3\\envs\\python_for_data_analysis\\lib\\site-packages\\dash\\_callback.py\", line 151, in add_context\n",
      "    output_value = func(*func_args, **func_kwargs)  # %% callback invoked %%\n",
      "  File \"<ipython-input-173-1ce2b5b6bbc8>\", line 31, in get_prediction_lineplot\n",
      "    model = models[model_name]()\n",
      "KeyError: None\n",
      "Exception on /_dash-update-component [POST]\n",
      "Traceback (most recent call last):\n",
      "  File \"C:\\Users\\10011\\anaconda3\\envs\\python_for_data_analysis\\lib\\site-packages\\flask\\app.py\", line 2073, in wsgi_app\n",
      "    response = self.full_dispatch_request()\n",
      "  File \"C:\\Users\\10011\\anaconda3\\envs\\python_for_data_analysis\\lib\\site-packages\\flask\\app.py\", line 1518, in full_dispatch_request\n",
      "    rv = self.handle_user_exception(e)\n",
      "  File \"C:\\Users\\10011\\anaconda3\\envs\\python_for_data_analysis\\lib\\site-packages\\flask\\app.py\", line 1516, in full_dispatch_request\n",
      "    rv = self.dispatch_request()\n",
      "  File \"C:\\Users\\10011\\anaconda3\\envs\\python_for_data_analysis\\lib\\site-packages\\flask\\app.py\", line 1502, in dispatch_request\n",
      "    return self.ensure_sync(self.view_functions[rule.endpoint])(**req.view_args)\n",
      "  File \"C:\\Users\\10011\\anaconda3\\envs\\python_for_data_analysis\\lib\\site-packages\\dash\\dash.py\", line 1345, in dispatch\n",
      "    response.set_data(func(*args, outputs_list=outputs_list))\n",
      "  File \"C:\\Users\\10011\\anaconda3\\envs\\python_for_data_analysis\\lib\\site-packages\\dash\\_callback.py\", line 151, in add_context\n",
      "    output_value = func(*func_args, **func_kwargs)  # %% callback invoked %%\n",
      "  File \"<ipython-input-173-1ce2b5b6bbc8>\", line 31, in get_prediction_lineplot\n",
      "    model = models[model_name]()\n",
      "KeyError: None\n",
      "Exception on /_dash-update-component [POST]\n",
      "Traceback (most recent call last):\n",
      "  File \"C:\\Users\\10011\\anaconda3\\envs\\python_for_data_analysis\\lib\\site-packages\\flask\\app.py\", line 2073, in wsgi_app\n",
      "    response = self.full_dispatch_request()\n",
      "  File \"C:\\Users\\10011\\anaconda3\\envs\\python_for_data_analysis\\lib\\site-packages\\flask\\app.py\", line 1518, in full_dispatch_request\n",
      "    rv = self.handle_user_exception(e)\n",
      "  File \"C:\\Users\\10011\\anaconda3\\envs\\python_for_data_analysis\\lib\\site-packages\\flask\\app.py\", line 1516, in full_dispatch_request\n",
      "    rv = self.dispatch_request()\n",
      "  File \"C:\\Users\\10011\\anaconda3\\envs\\python_for_data_analysis\\lib\\site-packages\\flask\\app.py\", line 1502, in dispatch_request\n",
      "    return self.ensure_sync(self.view_functions[rule.endpoint])(**req.view_args)\n",
      "  File \"C:\\Users\\10011\\anaconda3\\envs\\python_for_data_analysis\\lib\\site-packages\\dash\\dash.py\", line 1345, in dispatch\n",
      "    response.set_data(func(*args, outputs_list=outputs_list))\n",
      "  File \"C:\\Users\\10011\\anaconda3\\envs\\python_for_data_analysis\\lib\\site-packages\\dash\\_callback.py\", line 151, in add_context\n",
      "    output_value = func(*func_args, **func_kwargs)  # %% callback invoked %%\n",
      "  File \"<ipython-input-173-1ce2b5b6bbc8>\", line 31, in get_prediction_lineplot\n",
      "    model = models[model_name]()\n",
      "KeyError: None\n",
      "Exception on /_dash-update-component [POST]\n",
      "Traceback (most recent call last):\n",
      "  File \"C:\\Users\\10011\\anaconda3\\envs\\python_for_data_analysis\\lib\\site-packages\\flask\\app.py\", line 2073, in wsgi_app\n",
      "    response = self.full_dispatch_request()\n",
      "  File \"C:\\Users\\10011\\anaconda3\\envs\\python_for_data_analysis\\lib\\site-packages\\flask\\app.py\", line 1518, in full_dispatch_request\n",
      "    rv = self.handle_user_exception(e)\n",
      "  File \"C:\\Users\\10011\\anaconda3\\envs\\python_for_data_analysis\\lib\\site-packages\\flask\\app.py\", line 1516, in full_dispatch_request\n",
      "    rv = self.dispatch_request()\n",
      "  File \"C:\\Users\\10011\\anaconda3\\envs\\python_for_data_analysis\\lib\\site-packages\\flask\\app.py\", line 1502, in dispatch_request\n",
      "    return self.ensure_sync(self.view_functions[rule.endpoint])(**req.view_args)\n",
      "  File \"C:\\Users\\10011\\anaconda3\\envs\\python_for_data_analysis\\lib\\site-packages\\dash\\dash.py\", line 1345, in dispatch\n",
      "    response.set_data(func(*args, outputs_list=outputs_list))\n",
      "  File \"C:\\Users\\10011\\anaconda3\\envs\\python_for_data_analysis\\lib\\site-packages\\dash\\_callback.py\", line 151, in add_context\n",
      "    output_value = func(*func_args, **func_kwargs)  # %% callback invoked %%\n",
      "  File \"<ipython-input-173-1ce2b5b6bbc8>\", line 31, in get_prediction_lineplot\n",
      "    model = models[model_name]()\n",
      "KeyError: None\n",
      "Exception on /_dash-update-component [POST]\n",
      "Traceback (most recent call last):\n",
      "  File \"C:\\Users\\10011\\anaconda3\\envs\\python_for_data_analysis\\lib\\site-packages\\flask\\app.py\", line 2073, in wsgi_app\n",
      "    response = self.full_dispatch_request()\n",
      "  File \"C:\\Users\\10011\\anaconda3\\envs\\python_for_data_analysis\\lib\\site-packages\\flask\\app.py\", line 1518, in full_dispatch_request\n",
      "    rv = self.handle_user_exception(e)\n",
      "  File \"C:\\Users\\10011\\anaconda3\\envs\\python_for_data_analysis\\lib\\site-packages\\flask\\app.py\", line 1516, in full_dispatch_request\n",
      "    rv = self.dispatch_request()\n",
      "  File \"C:\\Users\\10011\\anaconda3\\envs\\python_for_data_analysis\\lib\\site-packages\\flask\\app.py\", line 1502, in dispatch_request\n",
      "    return self.ensure_sync(self.view_functions[rule.endpoint])(**req.view_args)\n",
      "  File \"C:\\Users\\10011\\anaconda3\\envs\\python_for_data_analysis\\lib\\site-packages\\dash\\dash.py\", line 1345, in dispatch\n",
      "    response.set_data(func(*args, outputs_list=outputs_list))\n",
      "  File \"C:\\Users\\10011\\anaconda3\\envs\\python_for_data_analysis\\lib\\site-packages\\dash\\_callback.py\", line 151, in add_context\n",
      "    output_value = func(*func_args, **func_kwargs)  # %% callback invoked %%\n",
      "  File \"<ipython-input-173-1ce2b5b6bbc8>\", line 31, in get_prediction_lineplot\n",
      "    model = models[model_name]()\n",
      "KeyError: None\n",
      "Exception on /_dash-update-component [POST]\n",
      "Traceback (most recent call last):\n",
      "  File \"C:\\Users\\10011\\anaconda3\\envs\\python_for_data_analysis\\lib\\site-packages\\flask\\app.py\", line 2073, in wsgi_app\n",
      "    response = self.full_dispatch_request()\n",
      "  File \"C:\\Users\\10011\\anaconda3\\envs\\python_for_data_analysis\\lib\\site-packages\\flask\\app.py\", line 1518, in full_dispatch_request\n",
      "    rv = self.handle_user_exception(e)\n",
      "  File \"C:\\Users\\10011\\anaconda3\\envs\\python_for_data_analysis\\lib\\site-packages\\flask\\app.py\", line 1516, in full_dispatch_request\n",
      "    rv = self.dispatch_request()\n",
      "  File \"C:\\Users\\10011\\anaconda3\\envs\\python_for_data_analysis\\lib\\site-packages\\flask\\app.py\", line 1502, in dispatch_request\n",
      "    return self.ensure_sync(self.view_functions[rule.endpoint])(**req.view_args)\n",
      "  File \"C:\\Users\\10011\\anaconda3\\envs\\python_for_data_analysis\\lib\\site-packages\\dash\\dash.py\", line 1345, in dispatch\n",
      "    response.set_data(func(*args, outputs_list=outputs_list))\n",
      "  File \"C:\\Users\\10011\\anaconda3\\envs\\python_for_data_analysis\\lib\\site-packages\\dash\\_callback.py\", line 151, in add_context\n",
      "    output_value = func(*func_args, **func_kwargs)  # %% callback invoked %%\n",
      "  File \"<ipython-input-173-1ce2b5b6bbc8>\", line 31, in get_prediction_lineplot\n",
      "    model = models[model_name]()\n",
      "KeyError: None\n",
      "Exception on /_dash-update-component [POST]\n",
      "Traceback (most recent call last):\n",
      "  File \"C:\\Users\\10011\\anaconda3\\envs\\python_for_data_analysis\\lib\\site-packages\\flask\\app.py\", line 2073, in wsgi_app\n",
      "    response = self.full_dispatch_request()\n",
      "  File \"C:\\Users\\10011\\anaconda3\\envs\\python_for_data_analysis\\lib\\site-packages\\flask\\app.py\", line 1518, in full_dispatch_request\n",
      "    rv = self.handle_user_exception(e)\n",
      "  File \"C:\\Users\\10011\\anaconda3\\envs\\python_for_data_analysis\\lib\\site-packages\\flask\\app.py\", line 1516, in full_dispatch_request\n",
      "    rv = self.dispatch_request()\n",
      "  File \"C:\\Users\\10011\\anaconda3\\envs\\python_for_data_analysis\\lib\\site-packages\\flask\\app.py\", line 1502, in dispatch_request\n",
      "    return self.ensure_sync(self.view_functions[rule.endpoint])(**req.view_args)\n",
      "  File \"C:\\Users\\10011\\anaconda3\\envs\\python_for_data_analysis\\lib\\site-packages\\dash\\dash.py\", line 1345, in dispatch\n",
      "    response.set_data(func(*args, outputs_list=outputs_list))\n",
      "  File \"C:\\Users\\10011\\anaconda3\\envs\\python_for_data_analysis\\lib\\site-packages\\dash\\_callback.py\", line 151, in add_context\n",
      "    output_value = func(*func_args, **func_kwargs)  # %% callback invoked %%\n",
      "  File \"<ipython-input-173-1ce2b5b6bbc8>\", line 31, in get_prediction_lineplot\n",
      "    model = models[model_name]()\n",
      "KeyError: None\n",
      "Exception on /_dash-update-component [POST]\n",
      "Traceback (most recent call last):\n",
      "  File \"C:\\Users\\10011\\anaconda3\\envs\\python_for_data_analysis\\lib\\site-packages\\flask\\app.py\", line 2073, in wsgi_app\n",
      "    response = self.full_dispatch_request()\n",
      "  File \"C:\\Users\\10011\\anaconda3\\envs\\python_for_data_analysis\\lib\\site-packages\\flask\\app.py\", line 1518, in full_dispatch_request\n",
      "    rv = self.handle_user_exception(e)\n",
      "  File \"C:\\Users\\10011\\anaconda3\\envs\\python_for_data_analysis\\lib\\site-packages\\flask\\app.py\", line 1516, in full_dispatch_request\n",
      "    rv = self.dispatch_request()\n",
      "  File \"C:\\Users\\10011\\anaconda3\\envs\\python_for_data_analysis\\lib\\site-packages\\flask\\app.py\", line 1502, in dispatch_request\n",
      "    return self.ensure_sync(self.view_functions[rule.endpoint])(**req.view_args)\n",
      "  File \"C:\\Users\\10011\\anaconda3\\envs\\python_for_data_analysis\\lib\\site-packages\\dash\\dash.py\", line 1345, in dispatch\n",
      "    response.set_data(func(*args, outputs_list=outputs_list))\n",
      "  File \"C:\\Users\\10011\\anaconda3\\envs\\python_for_data_analysis\\lib\\site-packages\\dash\\_callback.py\", line 151, in add_context\n",
      "    output_value = func(*func_args, **func_kwargs)  # %% callback invoked %%\n",
      "  File \"<ipython-input-173-1ce2b5b6bbc8>\", line 31, in get_prediction_lineplot\n",
      "    model = models[model_name]()\n",
      "KeyError: None\n"
     ]
    },
    {
     "name": "stderr",
     "output_type": "stream",
     "text": [
      "ERROR:__main__:Exception on /_dash-update-component [POST]\n",
      "Traceback (most recent call last):\n",
      "  File \"C:\\Users\\10011\\anaconda3\\envs\\python_for_data_analysis\\lib\\site-packages\\flask\\app.py\", line 2073, in wsgi_app\n",
      "    response = self.full_dispatch_request()\n",
      "  File \"C:\\Users\\10011\\anaconda3\\envs\\python_for_data_analysis\\lib\\site-packages\\flask\\app.py\", line 1518, in full_dispatch_request\n",
      "    rv = self.handle_user_exception(e)\n",
      "  File \"C:\\Users\\10011\\anaconda3\\envs\\python_for_data_analysis\\lib\\site-packages\\flask\\app.py\", line 1516, in full_dispatch_request\n",
      "    rv = self.dispatch_request()\n",
      "  File \"C:\\Users\\10011\\anaconda3\\envs\\python_for_data_analysis\\lib\\site-packages\\flask\\app.py\", line 1502, in dispatch_request\n",
      "    return self.ensure_sync(self.view_functions[rule.endpoint])(**req.view_args)\n",
      "  File \"C:\\Users\\10011\\anaconda3\\envs\\python_for_data_analysis\\lib\\site-packages\\dash\\dash.py\", line 1345, in dispatch\n",
      "    response.set_data(func(*args, outputs_list=outputs_list))\n",
      "  File \"C:\\Users\\10011\\anaconda3\\envs\\python_for_data_analysis\\lib\\site-packages\\dash\\_callback.py\", line 151, in add_context\n",
      "    output_value = func(*func_args, **func_kwargs)  # %% callback invoked %%\n",
      "  File \"<ipython-input-173-1ce2b5b6bbc8>\", line 31, in get_prediction_lineplot\n",
      "    model = models[model_name]()\n",
      "KeyError: None\n",
      "127.0.0.1 - - [29/Mar/2022 03:24:51] \"POST /_dash-update-component HTTP/1.1\" 500 -\n",
      "INFO:werkzeug:127.0.0.1 - - [29/Mar/2022 03:24:51] \"\u001b[35m\u001b[1mPOST /_dash-update-component HTTP/1.1\u001b[0m\" 500 -\n"
     ]
    }
   ],
   "source": [
    "if __name__ == '__main__':\n",
    "    app.run_server(debug=False)"
   ]
  },
  {
   "cell_type": "code",
   "execution_count": null,
   "id": "9b3de565-9800-47d0-9fa3-6353a81a8fae",
   "metadata": {},
   "outputs": [],
   "source": []
  },
  {
   "cell_type": "code",
   "execution_count": null,
   "id": "833ec6c6-4739-444c-a875-603426b2d50e",
   "metadata": {},
   "outputs": [],
   "source": []
  },
  {
   "cell_type": "code",
   "execution_count": 143,
   "id": "2baeed83-1dc6-412e-993d-5852d7f71029",
   "metadata": {},
   "outputs": [],
   "source": []
  },
  {
   "cell_type": "code",
   "execution_count": null,
   "id": "06cc6fb1-8d47-45c2-9c0f-dcc6c29c698e",
   "metadata": {},
   "outputs": [],
   "source": []
  },
  {
   "cell_type": "code",
   "execution_count": null,
   "id": "620a67de-0d60-4707-b1e0-c9d872a41ed1",
   "metadata": {},
   "outputs": [],
   "source": []
  },
  {
   "cell_type": "code",
   "execution_count": null,
   "id": "97dadf54-7843-4920-872a-6b7729b1805a",
   "metadata": {},
   "outputs": [],
   "source": []
  }
 ],
 "metadata": {
  "kernelspec": {
   "display_name": "Python 3",
   "language": "python",
   "name": "python3"
  },
  "language_info": {
   "codemirror_mode": {
    "name": "ipython",
    "version": 3
   },
   "file_extension": ".py",
   "mimetype": "text/x-python",
   "name": "python",
   "nbconvert_exporter": "python",
   "pygments_lexer": "ipython3",
   "version": "3.7.10"
  }
 },
 "nbformat": 4,
 "nbformat_minor": 5
}
